<?xml version="1.0" encoding="utf-8"?>
<robot
  name="TT">
      <!-- Colors --> 
  <material name="black"> 
      <color rgba="0 0 0 1"/>
  </material>
  <material name="blue"> 
      <color rgba="0.6 0.7 0.8 0.9"/>
  </material>
  <material name="yellow"> 
      <color rgba="1 0.6 0 0.9"/>
  </material>
  <link
    name="base_link">
    <inertial>
      <origin
        xyz="-2.4406 -4.7902 -0.31232"
        rpy="0 0 0" />
      <mass
        value="16000" />
      <inertia
        ixx="103290"
        ixy="-5.3338E-12"
        ixz="1.5499E-13"
        iyy="74340"
        iyz="21268"
        izz="61126" />
    </inertial>
    <visual>
      <origin
        xyz="0 0 0"
        rpy="0 0 0" />
      <geometry>
        <mesh
          filename="package://TT/meshes/base_link.STL" />
      </geometry>
      <material
        name="blue">
        <!--color
          rgba=" 39 172 245 0.6" /-->
      </material>
    </visual>
    <collision>
      <origin
        xyz="0 0 0"
        rpy="0 0 0" />
      <geometry>
        <mesh
          filename="package://TT/meshes/base_link.STL" />
      </geometry>
    </collision>
  </link>
  <link
    name="Left_Hinge">
    <inertial>
      <origin
        xyz="0.044267 -0.15 0"
        rpy="0 0 0" />
      <mass
        value="11.976" />
      <inertia
        ixx="0.15149"
        ixy="4.7995E-18"
        ixz="-2.2287E-18"
        iyy="0.23945"
        iyz="-1.7421E-34"
        izz="0.23529" />
    </inertial>
    <visual>
      <origin
        xyz="0 0 0"
        rpy="0 0 0" />
      <geometry>
        <mesh
          filename="package://TT/meshes/Left_Hinge.STL" />
      </geometry>
      <material
        name="">
        <color
          rgba="1 1 1 1" />
      </material>
    </visual>
    <collision>
      <origin
        xyz="0 0 0"
        rpy="0 0 0" />
      <geometry>
        <mesh
          filename="package://TT/meshes/Left_Hinge.STL" />
      </geometry>
    </collision>
  </link>
  <joint
    name="base_to_left_hinge"
    type="revolute">
    <origin
      xyz="-1.4156 -5.504 -2.0935"
      rpy="1.5708 0 0" />
    <parent
      link="base_link" />
    <child
      link="Left_Hinge" />
    <axis
      xyz="0 1 0" />
    <limit
      lower="-0.55"
      upper="0.55"
      effort="0"
      velocity="0.713" />
  </joint>
  <link
    name="left_front_tire">
    <inertial>
      <origin
        xyz="0.15107 8.8818E-16 -1.7764E-15"
        rpy="0 0 0" />
      <mass
        value="16" />
      <inertia
        ixx="14.659"
        ixy="6.5806E-16"
        ixz="-9.8805E-16"
        iyy="8.5568"
        iyz="-4.4409E-16"
        izz="8.5568" />
    </inertial>
    <visual>
      <origin
        xyz="0 0 0"
        rpy="0 0 0" />
      <geometry>
        <mesh
          filename="package://TT/meshes/left_front_tire.STL" />
      </geometry>
      <material
        name="">
        <color
          rgba="0 0 0 1" />
      </material>
    </visual>
    <collision>
      <origin
        xyz="0 0 0"
        rpy="0 0 0" />
      <geometry>
        <mesh
          filename="package://TT/meshes/left_front_tire.STL" />
      </geometry>
    </collision>
  </link>
  <joint
    name="left_hinge_to_tire"
    type="continuous">
    <origin
      xyz="0.175 -0.15 0"
      rpy="1.1065 0 0" />
    <parent
      link="Left_Hinge" />
    <child
      link="left_front_tire" />
    <axis
      xyz="1 0 0" />
  </joint>
  <link
    name="Right_Hinge">
    <inertial>
      <origin
        xyz="0.044267 -0.15 8.8818E-16"
        rpy="0 0 0" />
      <mass
        value="11.976" />
      <inertia
        ixx="0.15149"
        ixy="-1.3253E-17"
        ixz="1.9137E-18"
        iyy="0.23945"
        iyz="-4.3647E-18"
        izz="0.23529" />
    </inertial>
    <visual>
      <origin
        xyz="0 0 0"
        rpy="0 0 0" />
      <geometry>
        <mesh
          filename="package://TT/meshes/Right_Hinge.STL" />
      </geometry>
      <material
        name="">
        <color
          rgba="1 1 1 1" />
      </material>
    </visual>
    <collision>
      <origin
        xyz="0 0 0"
        rpy="0 0 0" />
      <geometry>
        <mesh
          filename="package://TT/meshes/Right_Hinge.STL" />
      </geometry>
    </collision>
  </link>
  <joint
    name="base_to_right_hinge"
    type="revolute">
    <origin
      xyz="-3.4656 -5.504 -2.0935"
      rpy="1.5708 0 3.1416" />
    <parent
      link="base_link" />
    <child
      link="Right_Hinge" />
    <axis
      xyz="0 1 0" />
    <limit
      lower="-0.55"
      upper="0.55"
      effort="0"
      velocity="0.7103" />
  </joint>
  <link
    name="right_front_tire">
    <inertial>
      <origin
        xyz="0.15107 8.8818E-16 8.8818E-16"
        rpy="0 0 0" />
      <mass
        value="16" />
      <inertia
        ixx="14.659"
        ixy="4.2107E-16"
        ixz="-1.0042E-15"
        iyy="8.5568"
        iyz="-8.8818E-16"
        izz="8.5568" />
    </inertial>
    <visual>
      <origin
        xyz="0 0 0"
        rpy="0 0 0" />
      <geometry>
        <mesh
          filename="package://TT/meshes/right_front_tire.STL" />
      </geometry>
      <material
        name="">
        <color
          rgba="0 0 0 1" />
      </material>
    </visual>
    <collision>
      <origin
        xyz="0 0 0"
        rpy="0 0 0" />
      <geometry>
        <mesh
          filename="package://TT/meshes/right_front_tire.STL" />
      </geometry>
    </collision>
  </link>
  <joint
    name="right_hinge_to_tire"
    type="continuous">
    <origin
      xyz="0.175 -0.15 0"
      rpy="-2.107 0 0" />
    <parent
      link="Right_Hinge" />
    <child
      link="right_front_tire" />
    <axis
      xyz="-1 0 0" />
  </joint>
  <link
    name="Left_Rear_Tire">
    <inertial>
      <origin
        xyz="-0.14893 -1.1102E-16 0"
        rpy="0 0 0" />
      <mass
        value="16" />
      <inertia
        ixx="14.659"
        ixy="8.0908E-17"
        ixz="2.6649E-16"
        iyy="8.5568"
        iyz="8.8818E-16"
        izz="8.5568" />
    </inertial>
    <visual>
      <origin
        xyz="0 0 0"
        rpy="0 0 0" />
      <geometry>
        <mesh
          filename="package://TT/meshes/Left_Rear_Tire.STL" />
      </geometry>
      <material
        name="">
        <color
          rgba="0 0 0 1" />
      </material>
    </visual>
    <collision>
      <origin
        xyz="0 0 0"
        rpy="0 0 0" />
      <geometry>
        <mesh
          filename="package://TT/meshes/Left_Rear_Tire.STL" />
      </geometry>
    </collision>
  </link>
  <joint
    name="base_to_left_rear_tire"
    type="continuous">
    <origin
      xyz="-1.2156 -1.904 -2.2435"
      rpy="2.0942 0 0" />
    <parent
      link="base_link" />
    <child
      link="Left_Rear_Tire" />
    <axis
      xyz="1 0 0" />
  </joint>
  <link
    name="Right_Rear_Tire">
    <inertial>
      <origin
        xyz="0.15107 2.2204E-16 8.8818E-16"
        rpy="0 0 0" />
      <mass
        value="16" />
      <inertia
        ixx="14.659"
        ixy="-3.1348E-17"
        ixz="-4.5026E-17"
        iyy="8.5568"
        iyz="1.7764E-15"
        izz="8.5568" />
    </inertial>
    <visual>
      <origin
        xyz="0 0 0"
        rpy="0 0 0" />
      <geometry>
        <mesh
          filename="package://TT/meshes/Right_Rear_Tire.STL" />
      </geometry>
      <material
        name="">
        <color
          rgba="0 0 0 1" />
      </material>
    </visual>
    <collision>
      <origin
        xyz="0 0 0"
        rpy="0 0 0" />
      <geometry>
        <mesh
          filename="package://TT/meshes/Right_Rear_Tire.STL" />
      </geometry>
    </collision>
  </link>
  <joint
    name="base_to_right_rear_tire"
    type="continuous">
    <origin
      xyz="-3.3656 -1.904 -2.2435"
      rpy="1.3179 0 3.1416" />
    <parent
      link="base_link" />
    <child
      link="Right_Rear_Tire" />
    <axis
      xyz="1 0 0" />
  </joint>
  <link
    name="Trailer">
    <inertial>
      <origin
        xyz="5.9508E-14 0.17326 -5.4942"
        rpy="0 0 0" />
      <mass
        value="12000" />
      <inertia
        ixx="2459700"
        ixy="9.4292E-10"
        ixz="2.3363E-08"
        iyy="2294600"
        iyz="-85390"
        izz="327600" />
    </inertial>
    <visual>
      <origin
        xyz="0 0 0"
        rpy="0 0 0" />
      <geometry>
        <mesh
          filename="package://TT/meshes/Trailer.STL" />
      </geometry>
      <material
        name="yellow">
        <!--color
          rgba="245 121 39 0.8" /-->
      </material>
    </visual>
    <collision>
      <origin
        xyz="0 0 0"
        rpy="0 0 0" />
      <geometry>
        <mesh
          filename="package://TT/meshes/Trailer.STL" />
      </geometry>
    </collision>
  </link>
  <joint
    name="Tractor_to_Trailer"
    type="revolute">
    <origin
      xyz="-2.4406 -1.904 0"
      rpy="1.5708 0 0.0093775" />
    <parent
      link="base_link" />
    <child
      link="Trailer" />
    <axis
      xyz="0 1 0" />
    <limit
      lower="-1.57"
      upper="1.57"
      effort="0"
      velocity="0" />
  </joint>
  <link
    name="Trailer_Left_Tire">
    <inertial>
      <origin
        xyz="0.15105 -5.1514E-14 -3.1974E-14"
        rpy="0 0 0" />
      <mass
        value="16" />
      <inertia
        ixx="14.659"
        ixy="4.8916E-18"
        ixz="6.5135E-14"
        iyy="8.5568"
        iyz="2.5319E-29"
        izz="8.5568" />
    </inertial>
    <visual>
      <origin
        xyz="0 0 0"
        rpy="0 0 0" />
      <geometry>
        <mesh
          filename="package://TT/meshes/Trailer_Left_Tire.STL" />
      </geometry>
      <material
        name="">
        <color
          rgba="0 0 0 1" />
      </material>
    </visual>
    <collision>
      <origin
        xyz="0 0 0"
        rpy="0 0 0" />
      <geometry>
        <mesh
          filename="package://TT/meshes/Trailer_Left_Tire.STL" />
      </geometry>
    </collision>
  </link>
  <joint
    name="trailer_to_left_tire"
    type="continuous">
    <origin
      xyz="0.92503 -2.2435 -8.1"
      rpy="0 0 0" />
    <parent
      link="Trailer" />
    <child
      link="Trailer_Left_Tire" />
    <axis
      xyz="1 0 0" />
  </joint>
  <link
    name="Trailer_Right_Tire">
    <inertial>
      <origin
        xyz="0.15105 2.0428E-14 5.7288E-14"
        rpy="0 0 0" />
      <mass
        value="16" />
      <inertia
        ixx="14.659"
        ixy="5.014E-14"
        ixz="1.9098E-14"
        iyy="8.5568"
        iyz="4.4409E-16"
        izz="8.5568" />
    </inertial>
    <visual>
      <origin
        xyz="0 0 0"
        rpy="0 0 0" />
      <geometry>
        <mesh
          filename="package://TT/meshes/Trailer_Right_Tire.STL" />
      </geometry>
      <material
        name="">
        <color
          rgba="0 0 0 1" />
      </material>
    </visual>
    <collision>
      <origin
        xyz="0 0 0"
        rpy="0 0 0" />
      <geometry>
        <mesh
          filename="package://TT/meshes/Trailer_Right_Tire.STL" />
      </geometry>
    </collision>
  </link>
  <joint
    name="trailer_to_right_tire"
    type="continuous">
    <origin
      xyz="-0.92503 -2.2435 -8.1"
      rpy="-1.8703 0 3.1416" />
    <parent
      link="Trailer" />
    <child
      link="Trailer_Right_Tire" />
    <axis
      xyz="1 0 0" />
  </joint>
</robot>
